<mujoco>
	<body mocap="true" name="robot0:mocap" pos="0 0 0">
		<geom conaffinity="0" contype="0" pos="0 0 0" rgba="0 0.5 0 0.7" size="0.005 0.005 0.005" type="box"></geom>
		<geom conaffinity="0" contype="0" pos="0 0 0" rgba="0 0.5 0 0.1" size="1 0.005 0.005" type="box"></geom>
		<geom conaffinity="0" contype="0" pos="0 0 0" rgba="0 0.5 0 0.1" size="0.005 1 0.001" type="box"></geom>
		<geom conaffinity="0" contype="0" pos="0 0 0" rgba="0 0.5 0 0.1" size="0.005 0.005 1" type="box"></geom>
	</body>
	<body childclass="robot0:fetch" name="robot0:base_link" pos="0 0 0.45" euler="0 -1.57079 0">
		<joint armature="0.0001" axis="1 0 0" damping="1e+11" name="robot0:slide0" pos="0 0 0" type="slide"></joint>
		<joint armature="0.0001" axis="0 1 0" damping="1e+11" name="robot0:slide1" pos="0 0 0" type="slide"></joint>
		<joint armature="0.0001" axis="0 0 1" damping="1e+11" name="robot0:slide2" pos="0 0 0" type="slide"></joint>
		<inertial diaginertia="1.2869 1.2236 0.9868" mass="70.1294" pos="-0.0036 0 0.0014" quat="0.7605 -0.0133 -0.0061 0.6491"></inertial>
		<body euler="0 0 0" name="robot0:gripper_link" pos="0.1664 0 0">
			<inertial diaginertia="0.0024 0.0019 0.0013" mass="1.5175" pos="-0.09 -0.0001 -0.0017"></inertial>
			<geom mesh="robot0:gripper_link" name="robot0:gripper_link" material="robot0:gripper_mat"></geom>
			<body name="robot0:gipper_camera_link" pos="0.055 0 0.0225">
				<body name="robot0:gripper_camera_rgb_frame" pos="0 0.02 0">
					<body name="robot0:gripper_camera_rgb_optical_frame" pos="0 0 0" quat="0.5 -0.5 0.5 -0.5">
						<camera euler="3.1415 0 0" fovy="50" name="gripper_camera_rgb" pos="0 0 0"></camera>
					</body>
				</body>
				<body name="robot0:gripper_camera_depth_frame" pos="0 0.045 0">
					<body name="robot0:gripper_camera_depth_optical_frame" pos="0 0 0" quat="0.5 -0.5 0.5 -0.5"></body>
				</body>
			</body>
			<body childclass="robot0:fetchGripper" name="robot0:r_gripper_finger_link" pos="0 0.0159 0">
				<inertial diaginertia="0.1 0.1 0.1" mass="4" pos="-0.01 0 0"></inertial>
				<joint axis="0 1 0" name="robot0:r_gripper_finger_joint" range="0 0.05"></joint>
				<geom pos="0 -0.008 0" size="0.0385 0.007 0.0135" type="box" name="robot0:r_gripper_finger_link" material="robot0:gripper_finger_mat" condim="4" friction="1 0.05 0.01"></geom>
			</body>
			<body childclass="robot0:fetchGripper" name="robot0:l_gripper_finger_link" pos="0 -0.0159 0">
				<inertial diaginertia="0.1 0.1 0.1" mass="4" pos="-0.01 0 0"></inertial>
				<joint axis="0 -1 0" name="robot0:l_gripper_finger_joint" range="0 0.05"></joint>
				<geom pos="0 0.008 0" size="0.0385 0.007 0.0135" type="box" name="robot0:l_gripper_finger_link" material="robot0:gripper_finger_mat" condim="4" friction="1 0.05 0.01"></geom>
			</body>
			<site name="robot0:grip" pos="0.02 0 0" rgba="0 0 0 0" size="0.02 0.02 0.02"></site>
		</body>
	</body>
</mujoco>
